Workbook

Sheet Customer_Dim
A1: Customer_ID | B1: Name | C1: Age | D1: Gender | E1: City | F1: State | G1: Country | H1: Loyalty_Level
A2: CUST1000 | B2: sheena bonilla | C2: 55 | D2: Male | E2: Donaldton | F2: North Carolina | G2: USA
A3: CUST1001 | B3: Eugene Nelson | C3: 26 | D3: Female | E3: Phillipsmouth | F3: North Dakota | G3: USA | H3: Platinum
A4: CUST1002 | B4: dr. Benjamin Price | C4: 29 | D4: Female | E4: Kylebury | F4: Alabama | G4: USA | H4: Platinum
A5: CUST1003 | B5: jeremy harris | C5: 59 | D5: Female | E5: Thomastown | F5: Ohio | G5: USA | H5: Bronze
A6: CUST1004 | B6: Caroline Collins | C6: 64 | D6: Female | E6: Nicholasshire | F6: California | G6: USA | H6: Silver
A7: CUST1005 | B7: Christine Vaughn | C7: 24 | D7: Male | E7: East Amandamouth | F7: Oregon | G7: USA | H7: Bronze
A8: CUST1006 | B8: Amber Jackson | C8: 29 | D8: Female | E8: Deborahborough | F8: South Dakota | G8: USA | H8: Platinum
A9: CUST1007 | B9: Daniel Boyd | C9: 29 | D9: Female | E9: West Pamelafurt | F9: West Virginia | G9: USA | H9: Bronze
A10: CUST1008 | B10: Melissa Howard | C10: 53 | D10: Female | E10: Maynardton | F10: New Hampshire | G10: USA | H10: Gold
A11: CUST1009 | B11: Ms. Maria Leach | C11: 64 | D11: Male | E11: Melissashire | F11: Pennsylvania | G11: USA | H11: Platinum
A12: CUST1010 | B12: Dominic Page | C12: 53 | D12: Male | E12: Port Michaelburgh | F12: Pennsylvania | G12: USA | H12: Bronze
A13: CUST1011 | B13: Brian Lopez | C13: 28 | D13: Female | E13: East Krista | F13: New York | G13: USA | H13: Gold
A14: CUST1012 | B14: Kenneth Lambert | C14: 55 | D14: Female | E14: North Kathryn | F14: Kansas | G14: USA | H14: Platinum
... A19: CUST1017 | B19: Adam Cruz | C19: 60 | D19: Female | E19: Brandonville | F19: Georgia | G19: USA | H19: Platinum
A20: CUST1018 | B20: Rhonda Moss | C20: 43 | D20: Male | E20: South William | F20: Kansas | G20: USA
A21: CUST1019 | B21: Michael Torres | C21: 46 | D21: Female | E21: Gonzalezfort | F21: New Jersey | G21: USA | H21: Platinum
A22: CUST1020 | B22: Bridget Allen | C22: 59 | D22: Male | E22: Lake Shaneburgh | F22: Delaware | G22: USA | H22: Silver
A23: CUST1021 | B23: Jeff Martinez | C23: 36 | D23: Female | E23: Smithburgh | F23: Oklahoma | G23: USA | H23: Gold
A24: CUST1022 | B24: paul fox | C24: 33 | D24: Female | E24: Michaelton | F24: Hawaii | G24: USA | H24: Silver
A25: CUST1023 | B25: Jonathan Steele | C25: 52 | D25: Female | E25: Molinabury | F25: Oregon | G25: USA | H25: Silver
A26: CUST1024 | B26: Heather Collins | C26: 40 | D26: Male | E26: Rogerschester | F26: Idaho | G26: USA | H26: Platinum
A27: CUST1025 | B27: Diana Taylor | C27: 59 | D27: Female | E27: Vasqueztown | F27: California | G27: USA | H27: Bronze
A28: CUST1026 | B28: Amber Carlson | C28: 18 | D28: Female | E28: East Michellemouth | F28: Missouri | G28: USA | H28: Gold
A29: CUST1027 | B29: Leslie Johnson | C29: 31 | D29: Male | E29: Mollyshire | F29: Utah | G29: USA
A30: CUST1028 | B30: Joshua Ryan | C30: 27 | D30: Female | E30: New David | F30: New Jersey | G30: USA | H30: Platinum
A31: CUST1029 | B31: David Arnold | C31: 54 | D31: Female | E31: East Jennifer | F31: California | G31: USA | H31: Silver
A32: CUST1030 | B32: Jessica Acevedo | C32: 64 | D32: Female | E32: Amybury | F32: Pennsylvania | G32: USA | H32: Bronze
A33: CUST1031 | B33: Sarah Vance | C33: 41 | D33: Male | E33: Johnsonville | F33: Oregon | G33: USA | H33: Silver
A34: CUST1032 | B34: Mike Jennings | C34: 48 | D34: Female | E34: Fostermouth | F34: Arizona | G34: USA | H34: Gold
A35: CUST1033 | B35: Robert Jones DDS | C35: 25 | D35: Male | E35: Tristanton | F35: Oklahoma | G35: USA | H35: Platinum
A36: CUST1034 | B36: Christopher Olson | C36: 27 | D36: Female | E36: West Richard | F36: Maryland | G36: USA | H36: Platinum
A37: CUST1035 | B37: Rachel Myers | C37: 52 | D37: Male | E37: Robertberg | F37: North Dakota | G37: USA | H37: Silver
A38: CUST1036 | B38: Thomas Phillips | C38: 20 | D38: Female | E38: Luisfurt | F38: Georgia | G38: USA | H38: Gold
A39: CUST1037 | B39: Christopher Carter | C39: 27 | D39: Female | E39: Brendastad | F39: South Dakota | G39: USA
A40: CUST1038 | B40: Deanna Simpson | C40: 35 | D40: Female | E40: Brownport | F40: North Dakota | G40: USA | H40: Bronze
A41: CUST1039 | B41: Tonya Reynolds | C41: 55 | D41: Female | E41: Darleneton | F41: Michigan | G41: USA | H41: Gold
A42: CUST1040 | B42: Eric Vega | C42: 50 | D42: Male | E42: Williamsonland | F42: Kansas | G42: USA | H42: Gold
A43: CUST1041 | B43: James Gibbs | C43: 21 | D43: Male | E43: Mooneyshire | F43: Alaska | G43: USA | H43: Platinum
A44: CUST1042 | B44: William Martin | C44: 19 | D44: Male | E44: Ryanburgh | F44: Connecticut | G44: USA | H44: Platinum
...

Sheet Product_Dim
A1: Product_ID | B1: Product_Name | C1: Category | D1: Sub_Category | E1: Brand | F1: Cost | G1: Stock
A2: PROD0 | B2: Brother Laser Printer | C2: Electronics | D2: Computer | E2: Hunt Inc | F2: 112.42 | G2: 416
A3: PROD1 | B3: Men's Graphic T-Shirt | C3: Clothing | D3: Tops | E3: Terry-Moore | F3: 342.56 | G3: 181
A4: PROD2 | B4: Women's Casual Hoodie | C4: Clothing | D4: Outerwear | E4: Sims Inc | F4: 358.47 | G4: 352
A5: PROD3 | B5: Men's Running Jacket | C5: Clothing | D5: Outerwear | E5: Pineda Ltd | F5: 364.67 | G5: 452
A6: PROD4 | B6: Women's Yoga Pants | C6: Clothing | D6: Bottoms | E6: Gonzales-Davis | F6: 306.46 | G6: 487
A7: PROD5 | B7: Men's Leather Belt | C7: Clothing | D7: Accessories | E7: Baldwin, Garza and Gonzalez | F7: 261 | G7: 59
A8: PROD6 | B8: Herbal Face Moisturizer | C8: Beauty | D8: Skincare | E8: Davidson PLC | F8: 312.8 | G8: 350
A9: PROD7 | B9: LED Table Lamp | C9: Home | D9: Lighting | E9: Harrell LLC | F9: 218.86 | G9: 170
A10: PROD8 | B10: Wireless Bluetooth Earbuds | C10: Electronics | D10: Audio | E10: Perez-Johnston | F10: 439.07 | G10: 142
A11: PROD9 | B11: Adjustable Dumbbell Set | C11: Sports | D11: Fitness | E11: Hill PLC | F11: 495.72 | G11: 323
A12: PROD10 | B12: Ceramic Kitchen Bowl Set | C12: Home | D12: Kitchen | E12: Hamilton Group | F12: 298.86 | G12: 308
A13: PROD11 | B13: HD Smart TV Stick | C13: Electronics | D13: Accessories | E13: Gibson, Hobbs and Weaver | F13: 449.4
A14: PROD12 | B14: Hair Strengthening Shampoo | C14: Beauty | D14: Haircare | E14: Rice LLC | F14: 115.82 | G14: 460
A15: PROD13 | B15: USB-C Fast Charger | C15: Electronics | D15: Accessories | E15: Dawson-Perkins | F15: 242.23 | G15: 453
A16: PROD14 | B16: Decorative Wall Mirror | C16: Home | D16: Decor | E16: Luna, Anderson and Bowman | F16: 48.01 | G16: 439
A17: PROD15 | B17: 4K Home Projector | C17: Electronics | D17: Appliances | E17: Thomas LLC | F17: 465.34 | G17: 301
A18: PROD16 | B18: Beard Grooming Kit | C18: Beauty | D18: Grooming | E18: Erickson-Green | F18: 337.42 | G18: 256
A19: PROD17 | B19: Soccer Training Cone Set | C19: Sports | D19: Accessories | E19: Ford, Murphy and Wilson | F19: 144.53 | G19: 367
A20: PROD18 | B20: Women's Denim Jeans | C20: Clothing | D20: Bottoms | E20: Guerra-Hendrix | F20: 306.46 | G20: 343
A21: PROD19 | B21: Knee Support Brace | C21: Sports | D21: Equipment | E21: May-Reese | F21: 21.34 | G21: 65
A22: PROD20 | B22: Outdoor Sports Water Bottle | C22: Sports | D22: Accessories | E22: Soto-Ellis | F22: 131.51
A23: PROD21 | B23: Multi-Purpose Storage Box | C23: Home | D23: Storage | E23: Gardner-Montes | F23: 123.46 | G23: 76
A24: PROD22 | B24: Carbon Fiber Tennis Racket | C24: Sports | D24: Equipment | E24: Flores, Pineda and Rodriguez | F24: 484.62 | G24: 432
A25: PROD23 | B25: Men's Formal Shirt | C25: Clothing | D25: Tops | E25: Moon, Mora and Santos | F25: 342.56 | G25: 360
A26: PROD24 | B26: Foldable Camping Chair | C26: Sports | D26: Outdoor | E26: Cook Ltd | F26: 166.06 | G26: 340
A27: PROD25 | B27: Women's Scarf Set | C27: Clothing | D27: Accessories | E27: Brown and Sons | F27: 174.02 | G27: 268
A28: PROD26 | B28: Wireless Bluetooth Speaker | C28: Electronics | D28: Audio | E28: Reed-Schmidt | F28: 322.41 | G28: 213
A29: PROD27 | B29: Decorative Floor Vase | C29: Home | D29: Decor | E29: Khan, Jones and Paul | G29: 378
A30: PROD28 | B30: Sports Stopwatch Timer | C30: Sports | D30: Accessories | E30: Burns-Hansen | F30: 38.76 | G30: 137
A31: PROD29 | B31: Fabric Sofa Throw Blanket | C31: Home | D31: Decor | E31: Hoffman Group | F31: 218.48 | G31: 276
A32: PROD30 | B32: Stainless Steel Cutlery Set | C32: Home | D32: Kitchen | E32: Stevens, Fernandez and Martin | F32: 19.52 | G32: 57
A33: PROD31 | B33: Basketball | C33: Sports | D33: Team Sports | E33: Nolan-Snow | F33: 204.39 | G33: 281
A34: PROD32 | B34: Vitamin C Face Serum | C34: Beauty | D34: Skincare | E34: Griffin Ltd | F34: 283.83 | G34: 244
A35: PROD33 | B35: Modern Wall Clock | C35: Home | D35: Decor | E35: Weiss-Watson | F35: 179.77 | G35: 305
A36: PROD34 | B36: Gaming Mechanical Keyboard | C36: Electronics | D36: Computer | E36: Lucero LLC | F36: 419.28 | G36: 86
A37: PROD35 | B37: Bedroom Table Lamp | C37: Home | D37: Lighting | E37: Jones LLC | F37: 382.22 | G37: 329
A38: PROD36 | B38: Women's Summer Dress | C38: Clothing | D38: Tops | E38: Smith-Mills | F38: 223.43 | G38: 154
A39: PROD37 | B39: Men's Casual Sneakers | C39: Clothing | D39: Footwear | E39: Hogan-Lee | F39: 353.47 | G39: 214
A40: PROD38 | B40: Sports Water Hydration Pack | C40: Sports | D40: Outdoor | E40: Sims-Smith | F40: 135.61 | G40: 394
...

Sheet Store_Dim
A1: Store_ID | B1: Store_Name | C1: Region | D1: City | E1: Store_Type
A2: STORE0 | B2: Rivera-Warner | C2: East | D2: Washingtonfurt | E2: Flagship
A3: STORE1 | B3: Martinez, Adkins and Johnson | C3: North | D3: Danielmouth | E3: Flagship
A4: STORE2 | B4: Black-Horn | C4: South | D4: North Nancyview | E4: Outlet
A5: STORE3 | B5: Johnson-Wright | C5: North | D5: Hoodberg | E5: Outlet
A6: STORE4 | B6: Alexander Group | C6: South | D6: Port Sharon | E6: Online
A7: STORE5 | B7: Gray Ltd | C7: North | D7: New Michaelchester | E7: Outlet
A8: STORE6 | B8: Benson-Elliott | C8: East | D8: Port Josephberg | E8: Online
A9: STORE7 | B9: Martinez-Mullins | C9: South | D9: Williamsfurt | E9: Online
A10: STORE8 | B10: Bean, Jones and Park | C10: West | D10: Thompsonborough | E10: Online
A11: STORE9 | B11: Moore, Padilla and Butler | C11: South | D11: East Johnstad | E11: Flagship
A12: STORE10 | B12: Hill, Wagner and Ballard | C12: East | D12: East Davidville | E12: Online
... A21: STORE19 | B21: Mann-Austin | C21: East | D21: Vasquezborough | E21: Online

Sheet Sales_Fact
A1: Sales_ID | B1: Order_Date | C1: Customer_ID | D1: Product_ID | E1: Store_ID | F1: Quantity | G1: Unit_Price | H1: Discount | I1: Payment_Type | J1: Total_Amount
A2: SALE0 | B2: 45480 | C2: CUST1409 | D2: PROD97 | E2: STORE3 | F2: 1 | G2: 218.04 | H2: 0.09 | I2: Credit Card | J2: 198.4164
A3: SALE1 | B3: 45285 | C3: CUST1467 | D3: PROD74 | E3: STORE17 | F3: 3 | G3: 104.47 | H3: 0.27 | I3: PayPal | J3: 228.7893
A4: SALE2 | B4: 45446 | C4: CUST1056 | D4: PROD49 | E4: STORE8 | F4: 4 | G4: 914.05 | H4: 0.25 | I4: Credit Card | J4: 2742.15
A5: SALE3 | B5: 45259 | C5: CUST1346 | D5: PROD76 | E5: STORE8 | F5: 1 | G5: 921.51 | H5: 0.16 | I5: COD | J5: 774.0684
A6: SALE4 | B6: 45297 | C6: CUST1493 | D6: PROD59 | E6: STORE5 | F6: 3 | G6: 745.3 | H6: 0.18 | I6: Credit Card | J6: 1833.438
A7: SALE5 | B7: 45499 | C7: CUST1116 | D7: PROD15 | E7: STORE7 | F7: 3 | G7: 147.01 | H7: 0.19 | I7: COD | J7: 357.2343
A8: SALE6 | B8: 45850 | C8: CUST1016 | D8: PROD56 | E8: STORE4 | F8: 2 | G8: 785.31 | H8: 0.15 | I8: PayPal | J8: 1335.027
A9: SALE7 | B9: 45248 | C9: CUST1152 | D9: PROD70 | E9: STORE8 | F9: 4 | G9: 342.39 | H9: 0.23 | I9: PayPal | J9: 1054.5612
A10: SALE8 | B10: 45781 | C10: CUST1187 | D10: PROD99 | E10: STORE5 | F10: 2 | G10: 448.25 | H10: 0.07 | I10: PayPal | J10: 1250.6175
A11: SALE9 | B11: 45869 | C11: CUST1464 | D11: PROD33 | E11: STORE0 | F11: 2 | G11: 873.17 | H11: 0.23 | I11: PayPal | J11: 1344.6818
A12: SALE10 | B12: 45335 | C12: CUST1065 | D12: PROD24 | E12: STORE14 | F12: 1 | G12: 278.63 | H12: 0.07 | I12: Credit Card | J12: 259.1259
A13: SALE11 | B13: 45801 | C13: CUST1320 | D13: PROD39 | E13: STORE1 | F13: 4 | G13: 286.92 | H13: 0.17 | I13: Credit Card | J13: 952.5744
... A20: SALE18 | B20: 45517 | C20: CUST1094 | D20: PROD39 | E20: STORE4 | F20: 2 | G20: 559.23 | H20: 0.25 | I20: COD | J20: 838.845
A21: SALE19 | B21: 45369 | C21: CUST1239 | D21: PROD60 | E21: STORE13 | F21: 4 | G21: =((J21*H21+J21)/F21) -> 463.43731 | H21: 0.04 | I21: COD | J21: 1782.4512
A22: SALE20 | B22: 45843 | C22: CUST1144 | D22: PROD72 | E22: STORE17 | F22: 3 | G22: 986.04 | H22: 0.27 | I22: COD | J22: 2159.4276
A23: SALE21 | B23: 45447 | C23: CUST1396 | D23: PROD43 | E23: STORE18 | F23: 1 | G23: 589.56 | H23: 0.22 | I23: Credit Card | J23: 459.8568
A24: SALE22 | B24: 45394 | C24: CUST1476 | D24: PROD69 | E24: STORE10 | F24: 3 | G24: 979.42 | H24: 0.03 | I24: PayPal | J24: 2850.1122
A25: SALE23 | B25: 45466 | C25: CUST1368 | D25: PROD12 | E25: STORE8 | F25: 1 | G25: 719.28 | H25: 0.08 | I25: Credit Card | J25: 661.7376
A26: SALE24 | B26: 45908 | C26: CUST1186 | D26: PROD67 | E26: STORE6 | F26: 3 | G26: 77.6 | H26: 0.07 | I26: Credit Card | J26: 216.504
A27: SALE25 | B27: 45552 | C27: CUST1381 | D27: PROD5 | E27: STORE3 | F27: 4 | G27: 852.71 | H27: 0.14 | I27: PayPal | J27: 2933.3224
A28: SALE26 | B28: 45294 | C28: CUST1213 | D28: PROD98 | E28: STORE8 | F28: 4 | G28: 156.16 | I28: Credit Card | J28: 599.6544
A29: SALE27 | B29: 45710 | C29: CUST1200 | D29: PROD77 | E29: STORE8 | F29: 3 | G29: 815.49 | H29: 0.17 | I29: Credit Card | J29: 2030.5701
A30: SALE28 | B30: 45923 | C30: CUST1148 | D30: PROD13 | E30: STORE2 | F30: 2 | G30: 74.21 | H30: 0.11 | I30: PayPal | J30: 132.0938
A31: SALE29 | B31: 45302 | C31: CUST1348 | D31: PROD99 | E31: STORE3 | F31: 2 | G31: 451.67 | H31: 0.15 | I31: Credit Card | J31: 1535.678
A32: SALE30 | B32: 45217 | C32: CUST1028 | D32: PROD5 | E32: STORE19 | F32: 1 | G32: 429.38 | H32: 0.13 | I32: PayPal | J32: 373.5606
A33: SALE31 | B33: 45593 | C33: CUST1412 | D33: PROD53 | E33: STORE12 | F33: 2 | G33: 148.96 | H33: 0.03 | I33: COD | J33: 288.9824
A34: SALE32 | B34: 45597 | C34: CUST1398 | D34: PROD75 | E34: STORE8 | F34: 4 | G34: 313.83 | H34: 0.08 | I34: Credit Card | J34: 1154.8944
A35: SALE33 | B35: 45620 | C35: CUST1453 | D35: PROD12 | E35: STORE6 | F35: 2 | G35: 717.31 | H35: 0.15 | I35: Credit Card | J35: 1219.427
A36: SALE34 | B36: 45215 | C36: CUST1344 | D36: PROD79 | E36: STORE1 | F36: 2 | G36: 873.22 | H36: 0.18 | I36: Credit Card | J36: 2148.1212
A37: SALE35 | B37: 45878 | C37: CUST1218 | D37: PROD16 | E37: STORE3 | F37: 4 | G37: 109.36 | H37: 0.19 | I37: COD | J37: 354.3264
A38: SALE36 | B38: 45635 | C38: CUST1086 | D38: PROD5 | E38: STORE7 | F38: 3 | G38: 559.52 | H38: 0.16 | I38: PayPal | J38: 1409.9904
A39: SALE37 | B39: 45329 | C39: CUST1492 | D39: PROD10 | E39: STORE17 | F39: 3 | G39: 121.76 | H39: 0.27 | I39: PayPal | J39: 266.6544
A40: SALE38 | B40: 45378 | C40: CUST1189 | D40: PROD33 | E40: STORE13 | F40: 4 | G40: 735.32 | H40: 0.06 | I40: COD | J40: 2764.8032
... A53: SALE51 | B53: 45689 | C53: CUST1142 | D53: PROD69 | E53: STORE7 | F53: 3 | G53: 76.57 | H53: 0.26 | I53: Credit Card | J53: 169.9854
A54: SALE52 | B54: 45894 | C54: CUST1148 | D54: PROD89 | E54: STORE6 | F54: 3 | G54: =((J54*H54+J54)/F54) -> 162.0211 | H54: 0 | I54: Credit Card | J54: 486.0633
A55: SALE53 | B55: 45677 | C55: CUST1324 | D55: PROD20 | E55: STORE8 | F55: 1 | G55: 900.35 | H55: 0.13 | I55: COD | J55: 783.3045
A56: SALE54 | B56: 45706 | C56: CUST1095 | D56: PROD40 | E56: STORE10 | F56: 4 | G56: 428.09 | H56: 0.07 | I56: Credit Card | J56: 1592.4948
A57: SALE55 | B57: 45589 | C57: CUST1416 | D57: PROD49 | E57: STORE11 | F57: 2 | G57: 559.71 | H57: 0.3 | I57: COD | J57: 783.594
A58: SALE56 | B58: 45282 | C58: CUST1080 | D58: PROD34 | E58: STORE6 | F58: 2 | G58: 833.7 | H58: 0.06 | I58: PayPal | J58: 1567.356
...

Sheet Cleaned Customer_Dim 
A1: Customer_ID | B1: Name | C1: Age | D1: Gender | E1: City | F1: State | G1: Country | H1: Loyalty_Level
A2: CUST1000 | B2: Sheena Bonilla | C2: 55 | D2: Male | E2: Donaldton | F2: North Carolina | G2: USA | H2: Platinum
A3: CUST1001 | B3: Eugene Nelson | C3: 26 | D3: Female | E3: Phillipsmouth | F3: North Dakota | G3: USA | H3: Platinum
A4: CUST1002 | B4: Dr. Benjamin Price | C4: 29 | D4: Female | E4: Kylebury | F4: Alabama | G4: USA | H4: Platinum
A5: CUST1003 | B5: Jeremy Harris | C5: 59 | D5: Female | E5: Thomastown | F5: Ohio | G5: USA | H5: Bronze
A6: CUST1004 | B6: Caroline Collins | C6: 64 | D6: Female | E6: Nicholasshire | F6: California | G6: USA | H6: Silver
A7: CUST1005 | B7: Christine Vaughn | C7: 24 | D7: Male | E7: East Amandamouth | F7: Oregon | G7: USA | H7: Bronze
A8: CUST1006 | B8: Amber Jackson | C8: 29 | D8: Female | E8: Deborahborough | F8: South Dakota | G8: USA | H8: Platinum
A9: CUST1007 | B9: Daniel Boyd | C9: 29 | D9: Female | E9: West Pamelafurt | F9: West Virginia | G9: USA | H9: Bronze
A10: CUST1008 | B10: Melissa Howard | C10: 53 | D10: Female | E10: Maynardton | F10: New Hampshire | G10: USA | H10: Gold
A11: CUST1009 | B11: Ms. Maria Leach | C11: 64 | D11: Male | E11: Melissashire | F11: Pennsylvania | G11: USA | H11: Platinum
A12: CUST1010 | B12: Dominic Page | C12: 53 | D12: Male | E12: Port Michaelburgh | F12: Pennsylvania | G12: USA | H12: Bronze
A13: CUST1011 | B13: Brian Lopez | C13: 28 | D13: Female | E13: East Krista | F13: New York | G13: USA | H13: Gold
... A501: CUST1499 | B501: Philip Pennington | C501: 27 | D501: Female | E501: East Valerieview | F501: Oregon | G501: USA | H501: Platinum

Sheet Cleaned Product_Dim 
A1: Product_ID | B1: Product_Name | C1: Category | D1: Sub_Category | E1: Brand | F1: Cost | G1: Stock | H1: Total Amount
A2: PROD0 | B2: Brother Laser Printer | C2: Electronics | D2: Computer | E2: Hunt Inc | F2: 112.42 | G2: 416 | H2: =Product_Dim__2[[#This Row],[Cost]]*Product_Dim__2[[#This Row],[Stock]] -> 46766.72
A3: PROD1 | B3: Men's Graphic T-Shirt | C3: Clothing | D3: Tops | E3: Terry-Moore | F3: 342.56 | G3: 181 | H3: =Product_Dim__2[[#This Row],[Cost]]*Product_Dim__2[[#This Row],[Stock]] -> 62003.36
A4: PROD2 | B4: Women's Casual Hoodie | C4: Clothing | D4: Outerwear | E4: Sims Inc | F4: 358.47 | G4: 352 | H4: =Product_Dim__2[[#This Row],[Cost]]*Product_Dim__2[[#This Row],[Stock]] -> 126181.44
A5: PROD3 | B5: Men's Running Jacket | C5: Clothing | D5: Outerwear | E5: Pineda Ltd | F5: 364.67 | G5: 452 | H5: =Product_Dim__2[[#This Row],[Cost]]*Product_Dim__2[[#This Row],[Stock]] -> 164830.84
A6: PROD4 | B6: Women's Yoga Pants | C6: Clothing | D6: Bottoms | E6: Gonzales-Davis | F6: 306.46 | G6: 487 | H6: =Product_Dim__2[[#This Row],[Cost]]*Product_Dim__2[[#This Row],[Stock]] -> 149246.02
A7: PROD5 | B7: Men's Leather Belt | C7: Clothing | D7: Accessories | E7: Baldwin, Garza and Gonzalez | F7: 261 | G7: 59 | H7: =Product_Dim__2[[#This Row],[Cost]]*Product_Dim__2[[#This Row],[Stock]] -> 15399
A8: PROD6 | B8: Herbal Face Moisturizer | C8: Beauty | D8: Skincare | E8: Davidson PLC | F8: 312.8 | G8: 350 | H8: =Product_Dim__2[[#This Row],[Cost]]*Product_Dim__2[[#This Row],[Stock]] -> 109480
A9: PROD7 | B9: LED Table Lamp | C9: Home | D9: Lighting | E9: Harrell LLC | F9: 218.86 | G9: 170 | H9: =Product_Dim__2[[#This Row],[Cost]]*Product_Dim__2[[#This Row],[Stock]] -> 37206.2
A10: PROD8 | B10: Wireless Bluetooth Earbuds | C10: Electronics | D10: Audio | E10: Perez-Johnston | F10: 439.07 | G10: 142 | H10: =Product_Dim__2[[#This Row],[Cost]]*Product_Dim__2[[#This Row],[Stock]] -> 62347.94
A11: PROD9 | B11: Adjustable Dumbbell Set | C11: Sports | D11: Fitness | E11: Hill PLC | F11: 495.72 | G11: 323 | H11: =Product_Dim__2[[#This Row],[Cost]]*Product_Dim__2[[#This Row],[Stock]] -> 160117.56
A12: PROD10 | B12: Ceramic Kitchen Bowl Set | C12: Home | D12: Kitchen | E12: Hamilton Group | F12: 298.86 | G12: 308 | H12: =Product_Dim__2[[#This Row],[Cost]]*Product_Dim__2[[#This Row],[Stock]] -> 92048.88
A13: PROD11 | B13: HD Smart TV Stick | C13: Electronics | D13: Accessories | E13: Gibson, Hobbs and Weaver | F13: 449.4 | G13: 275 | H13: =Product_Dim__2[[#This Row],[Cost]]*Product_Dim__2[[#This Row],[Stock]] -> 123585
... A101: PROD99 | B101: Stainless Steel Cookware Set | C101: Home | D101: Kitchen | E101: Campbell Ltd | F101: 201.41 | G101: 146 | H101: =Product_Dim__2[[#This Row],[Cost]]*Product_Dim__2[[#This Row],[Stock]] -> 29405.86
E104: Total No of Cost | F104: =SUM(F4:F103) -> 25168.43
E105: Total No of Stock | F105: =SUM(G2:G101) -> 27312
E106: Min of Cost | F106: =MIN(F2:F101) -> 17.31
E107: Ma f Cost | F107: =MAX(F2:F101) -> 495.72
E108: Average of Cost | F108: =AVERAGE(F8:F107) -> 784.40092
E109: Average of Stock | F109: =AVERAGE(G6:G105) -> 269.90625

Sheet Cleaned Store_Dim 
A1: Store_ID | B1: Store_Name | C1: Region | D1: Region2 | E1: Store_Type | F1: Store count
A2: STORE0 | B2: Rivera-Warner | C2: East | D2: Washingtonfurt | E2: Flagship | F2: =COUNTIF(Store_Dim__2[Store_Type],Store_Dim__2[[#This Row],[Store_Type]]) -> 8
A3: STORE1 | B3: Martinez, Adkins and Johnson | C3: North | D3: Danielmouth | E3: Flagship | F3: =COUNTIF(Store_Dim__2[Store_Type],Store_Dim__2[[#This Row],[Store_Type]]) -> 8
A4: STORE2 | B4: Black-Horn | C4: South | D4: North Nancyview | E4: Outlet | F4: =COUNTIF(Store_Dim__2[Store_Type],Store_Dim__2[[#This Row],[Store_Type]]) -> 4
A5: STORE3 | B5: Johnson-Wright | C5: North | D5: Hoodberg | E5: Outlet | F5: =COUNTIF(Store_Dim__2[Store_Type],Store_Dim__2[[#This Row],[Store_Type]]) -> 4
A6: STORE4 | B6: Alexander Group | C6: South | D6: Port Sharon | E6: Online | F6: =COUNTIF(Store_Dim__2[Store_Type],Store_Dim__2[[#This Row],[Store_Type]]) -> 8
A7: STORE5 | B7: Gray Ltd | C7: North | D7: New Michaelchester | E7: Outlet | F7: =COUNTIF(Store_Dim__2[Store_Type],Store_Dim__2[[#This Row],[Store_Type]]) -> 4
A8: STORE6 | B8: Benson-Elliott | C8: East | D8: Port Josephberg | E8: Online | F8: =COUNTIF(Store_Dim__2[Store_Type],Store_Dim__2[[#This Row],[Store_Type]]) -> 8
A9: STORE7 | B9: Martinez-Mullins | C9: South | D9: Williamsfurt | E9: Online | F9: =COUNTIF(Store_Dim__2[Store_Type],Store_Dim__2[[#This Row],[Store_Type]]) -> 8
A10: STORE8 | B10: Bean, Jones and Park | C10: West | D10: Thompsonborough | E10: Online | F10: =COUNTIF(Store_Dim__2[Store_Type],Store_Dim__2[[#This Row],[Store_Type]]) -> 8
A11: STORE9 | B11: Moore, Padilla and Butler | C11: South | D11: East Johnstad | E11: Flagship | F11: =COUNTIF(Store_Dim__2[Store_Type],Store_Dim__2[[#This Row],[Store_Type]]) -> 8
A12: STORE10 | B12: Hill, Wagner and Ballard | C12: East | D12: East Davidville | E12: Online | F12: =COUNTIF(Store_Dim__2[Store_Type],Store_Dim__2[[#This Row],[Store_Type]]) -> 8
A13: STORE11 | B13: Aguirre-Keller | C13: South | D13: Lake Michael | E13: Online | F13: =COUNTIF(Store_Dim__2[Store_Type],Store_Dim__2[[#This Row],[Store_Type]]) -> 8
... A21: STORE19 | B21: Mann-Austin | C21: East | D21: Vasquezborough | E21: Online | F21: =COUNTIF(Store_Dim__2[Store_Type],Store_Dim__2[[#This Row],[Store_Type]]) -> 8

Sheet Cleaned Sales_Fact 
A1: Sales_ID | B1: Order_Date | C1: Customer_ID | D1: Product_ID | E1: Store_ID | F1: Quantity | G1: Unit_Price | H1: Discount | I1: Payment_Type | J1: Total_Amount | K1: Creditcard Total Payment | L1: Column1
A2: SALE0 | B2: 45480 | C2: CUST1409 | D2: PROD97 | E2: STORE3 | F2: 1 | G2: 218.04 | H2: 0.09 | I2: Credit Card | J2: 198.4164 | K2: =COUNTIF(Sales_Fact[Payment_Type], "Credit Card") -> 645 | L2: =IF(J2>=1000, "Good", "Average") -> Average
A3: SALE1 | B3: 45285 | C3: CUST1467 | D3: PROD74 | E3: STORE17 | F3: 3 | G3: 104.47 | H3: 0.27 | I3: PayPal | J3: 228.7893 | K3: =COUNTIF(Sales_Fact[Payment_Type], "Credit Card") -> 645 | L3: =IF(J3>=1000, "Good", "Average") -> Average
A4: SALE2 | B4: 45446 | C4: CUST1056 | D4: PROD49 | E4: STORE8 | F4: 4 | G4: 914.05 | H4: 0.25 | I4: Credit Card | J4: 2742.15 | K4: =COUNTIF(Sales_Fact[Payment_Type], "Credit Card") -> 645 | L4: =IF(J4>=1000, "Good", "Average") -> Good
A5: SALE3 | B5: 45259 | C5: CUST1346 | D5: PROD76 | E5: STORE8 | F5: 1 | G5: 921.51 | H5: 0.16 | I5: COD | J5: 774.0684 | K5: =COUNTIF(Sales_Fact[Payment_Type], "Credit Card") -> 645 | L5: =IF(J5>=1000, "Good", "Average") -> Average
A6: SALE4 | B6: 45297 | C6: CUST1493 | D6: PROD59 | E6: STORE5 | F6: 3 | G6: 745.3 | H6: 0.18 | I6: Credit Card | J6: 1833.438 | K6: =COUNTIF(Sales_Fact[Payment_Type], "Credit Card") -> 645 | L6: =IF(J6>=1000, "Good", "Average") -> Good
A7: SALE5 | B7: 45499 | C7: CUST1116 | D7: PROD15 | E7: STORE7 | F7: 3 | G7: 147.01 | H7: 0.19 | I7: COD | J7: 357.2343 | K7: =COUNTIF(Sales_Fact[Payment_Type], "Credit Card") -> 645 | L7: =IF(J7>=1000, "Good", "Average") -> Average
A8: SALE6 | B8: 45850 | C8: CUST1016 | D8: PROD56 | E8: STORE4 | F8: 2 | G8: 785.31 | H8: 0.15 | I8: PayPal | J8: 1335.027 | K8: =COUNTIF(Sales_Fact[Payment_Type], "Credit Card") -> 645 | L8: =IF(J8>=1000, "Good", "Average") -> Good
A9: SALE7 | B9: 45248 | C9: CUST1152 | D9: PROD70 | E9: STORE8 | F9: 4 | G9: 342.39 | H9: 0.23 | I9: PayPal | J9: 1054.5612 | K9: =COUNTIF(Sales_Fact[Payment_Type], "Credit Card") -> 645 | L9: =IF(J9>=1000, "Good", "Average") -> Good
A10: SALE8 | B10: 45781 | C10: CUST1187 | D10: PROD99 | E10: STORE5 | F10: 2 | G10: 448.25 | H10: 0.07 | I10: PayPal | J10: 1250.6175 | K10: =COUNTIF(Sales_Fact[Payment_Type], "Credit Card") -> 645 | L10: =IF(J10>=1000, "Good", "Average") -> Good
A11: SALE9 | B11: 45869 | C11: CUST1464 | D11: PROD33 | E11: STORE0 | F11: 2 | G11: 873.17 | H11: 0.23 | I11: PayPal | J11: 1344.6818 | K11: =COUNTIF(Sales_Fact[Payment_Type], "Credit Card") -> 645 | L11: =IF(J11>=1000, "Good", "Average") -> Good
A12: SALE10 | B12: 45335 | C12: CUST1065 | D12: PROD24 | E12: STORE14 | F12: 1 | G12: 278.63 | H12: 0.07 | I12: Credit Card | J12: 259.1259 | K12: =COUNTIF(Sales_Fact[Payment_Type], "Credit Card") -> 645 | L12: =IF(J12>=1000, "Good", "Average") -> Average
A13: SALE11 | B13: 45801 | C13: CUST1320 | D13: PROD39 | E13: STORE1 | F13: 4 | G13: 286.92 | H13: 0.17 | I13: Credit Card | J13: 952.5744 | K13: =COUNTIF(Sales_Fact[Payment_Type], "Credit Card") -> 645 | L13: =IF(J13>=1000, "Good", "Average") -> Average
... A20: SALE18 | B20: 45517 | C20: CUST1094 | D20: PROD39 | E20: STORE4 | F20: 2 | G20: 559.23 | H20: 0.25 | I20: COD | J20: 838.845 | K20: =COUNTIF(Sales_Fact[Payment_Type], "Credit Card") -> 645 | L20: =IF(J20>=1000, "Good", "Average") -> Average
A21: SALE19 | B21: 45369 | C21: CUST1239 | D21: PROD60 | E21: STORE13 | F21: 4 | G21: =Sales_Fact[[#This Row],[Total_Amount]]/(Sales_Fact[[#This Row],[Quantity]]*(1-Sales_Fact[[#This Row],[Discount]])) -> 464.18 | H21: 0.04 | I21: COD | J21: 1782.4512 | K21: =COUNTIF(Sales_Fact[Payment_Type], "Credit Card") -> 645 | L21: =IF(J21>=1000, "Good", "Average") -> Good
A22: SALE20 | B22: 45843 | C22: CUST1144 | D22: PROD72 | E22: STORE17 | F22: 3 | G22: 986.04 | H22: 0.27 | I22: COD | J22: 2159.4276 | K22: =COUNTIF(Sales_Fact[Payment_Type], "Credit Card") -> 645 | L22: =IF(J22>=1000, "Good", "Average") -> Good
A23: SALE21 | B23: 45447 | C23: CUST1396 | D23: PROD43 | E23: STORE18 | F23: 1 | G23: 589.56 | H23: 0.22 | I23: Credit Card | J23: 459.8568 | K23: =COUNTIF(Sales_Fact[Payment_Type], "Credit Card") -> 645 | L23: =IF(J23>=1000, "Good", "Average") -> Average
A24: SALE22 | B24: 45394 | C24: CUST1476 | D24: PROD69 | E24: STORE10 | F24: 3 | G24: 979.42 | H24: 0.03 | I24: PayPal | J24: 2850.1122 | K24: =COUNTIF(Sales_Fact[Payment_Type], "Credit Card") -> 645 | L24: =IF(J24>=1000, "Good", "Average") -> Good
A25: SALE23 | B25: 45466 | C25: CUST1368 | D25: PROD12 | E25: STORE8 | F25: 1 | G25: 719.28 | H25: 0.08 | I25: Credit Card | J25: 661.7376 | K25: =COUNTIF(Sales_Fact[Payment_Type], "Credit Card") -> 645 | L25: =IF(J25>=1000, "Good", "Average") -> Average
A26: SALE24 | B26: 45908 | C26: CUST1186 | D26: PROD67 | E26: STORE6 | F26: 3 | G26: 77.6 | H26: 0.07 | I26: Credit Card | J26: 216.504 | K26: =COUNTIF(Sales_Fact[Payment_Type], "Credit Card") -> 645 | L26: =IF(J26>=1000, "Good", "Average") -> Average
A27: SALE25 | B27: 45552 | C27: CUST1381 | D27: PROD5 | E27: STORE3 | F27: 4 | G27: 852.71 | H27: 0.14 | I27: PayPal | J27: 2933.3224 | K27: =COUNTIF(Sales_Fact[Payment_Type], "Credit Card") -> 645 | L27: =IF(J27>=1000, "Good", "Average") -> Good
A28: SALE26 | B28: 45294 | C28: CUST1213 | D28: PROD98 | E28: STORE8 | F28: 4 | G28: 156.16 | H28: =1-(J28/(F28*G28)) -> 0.04 | I28: Credit Card | J28: 599.6544 | K28: =COUNTIF(Sales_Fact[Payment_Type], "Credit Card") -> 645 | L28: =IF(J28>=1000, "Good", "Average") -> Average
A29: SALE27 | B29: 45710 | C29: CUST1200 | D29: PROD77 | E29: STORE8 | F29: 3 | G29: 815.49 | H29: 0.17 | I29: Credit Card | J29: 2030.5701 | K29: =COUNTIF(Sales_Fact[Payment_Type], "Credit Card") -> 645 | L29: =IF(J29>=1000, "Good", "Average") -> Good
A30: SALE28 | B30: 45923 | C30: CUST1148 | D30: PROD13 | E30: STORE2 | F30: 2 | G30: 74.21 | H30: 0.11 | I30: PayPal | J30: 132.0938 | K30: =COUNTIF(Sales_Fact[Payment_Type], "Credit Card") -> 645 | L30: =IF(J30>=1000, "Good", "Average") -> Average
A31: SALE29 | B31: 45302 | C31: CUST1348 | D31: PROD99 | E31: STORE3 | F31: 2 | G31: 451.67 | H31: 0.15 | I31: Credit Card | J31: 1535.678 | K31: =COUNTIF(Sales_Fact[Payment_Type], "Credit Card") -> 645 | L31: =IF(J31>=1000, "Good", "Average") -> Good
A32: SALE30 | B32: 45217 | C32: CUST1028 | D32: PROD5 | E32: STORE19 | F32: 1 | G32: 429.38 | H32: 0.13 | I32: PayPal | J32: 373.5606 | K32: =COUNTIF(Sales_Fact[Payment_Type], "Credit Card") -> 645 | L32: =IF(J32>=1000, "Good", "Average") -> Average
A33: SALE31 | B33: 45593 | C33: CUST1412 | D33: PROD53 | E33: STORE12 | F33: 2 | G33: 148.96 | H33: 0.03 | I33: COD | J33: 288.9824 | K33: =COUNTIF(Sales_Fact[Payment_Type], "Credit Card") -> 645 | L33: =IF(J33>=1000, "Good", "Average") -> Average
A34: SALE32 | B34: 45597 | C34: CUST1398 | D34: PROD75 | E34: STORE8 | F34: 4 | G34: 313.83 | H34: 0.08 | I34: Credit Card | J34: 1154.8944 | K34: =COUNTIF(Sales_Fact[Payment_Type], "Credit Card") -> 645 | L34: =IF(J34>=1000, "Good", "Average") -> Good
A35: SALE33 | B35: 45620 | C35: CUST1453 | D35: PROD12 | E35: STORE6 | F35: 2 | G35: 717.31 | H35: 0.15 | I35: Credit Card | J35: 1219.427 | K35: =COUNTIF(Sales_Fact[Payment_Type], "Credit Card") -> 645 | L35: =IF(J35>=1000, "Good", "Average") -> Good
A36: SALE34 | B36: 45215 | C36: CUST1344 | D36: PROD79 | E36: STORE1 | F36: 2 | G36: 873.22 | H36: 0.18 | I36: Credit Card | J36: 2148.1212 | K36: =COUNTIF(Sales_Fact[Payment_Type], "Credit Card") -> 645 | L36: =IF(J36>=1000, "Good", "Average") -> Good
A37: SALE35 | B37: 45878 | C37: CUST1218 | D37: PROD16 | E37: STORE3 | F37: 4 | G37: 109.36 | H37: 0.19 | I37: COD | J37: 354.3264 | K37: =COUNTIF(Sales_Fact[Payment_Type], "Credit Card") -> 645 | L37: =IF(J37>=1000, "Good", "Average") -> Average
A38: SALE36 | B38: 45635 | C38: CUST1086 | D38: PROD5 | E38: STORE7 | F38: 3 | G38: 559.52 | H38: 0.16 | I38: PayPal | J38: 1409.9904 | K38: =COUNTIF(Sales_Fact[Payment_Type], "Credit Card") -> 645 | L38: =IF(J38>=1000, "Good", "Average") -> Good
A39: SALE37 | B39: 45329 | C39: CUST1492 | D39: PROD10 | E39: STORE17 | F39: 3 | G39: 121.76 | H39: 0.27 | I39: PayPal | J39: 266.6544 | K39: =COUNTIF(Sales_Fact[Payment_Type], "Credit Card") -> 645 | L39: =IF(J39>=1000, "Good", "Average") -> Average
A40: SALE38 | B40: 45378 | C40: CUST1189 | D40: PROD33 | E40: STORE13 | F40: 4 | G40: 735.32 | H40: 0.06 | I40: COD | J40: 2764.8032 | K40: =COUNTIF(Sales_Fact[Payment_Type], "Credit Card") -> 645 | L40: =IF(J40>=1000, "Good", "Average") -> Good
... A53: SALE51 | B53: 45689 | C53: CUST1142 | D53: PROD69 | E53: STORE7 | F53: 3 | G53: 76.57 | H53: 0.26 | I53: Credit Card | J53: 169.9854 | K53: =COUNTIF(Sales_Fact[Payment_Type], "Credit Card") -> 645 | L53: =IF(J53>=1000, "Good", "Average") -> Average
A54: SALE52 | B54: 45894 | C54: CUST1148 | D54: PROD89 | E54: STORE6 | F54: 3 | G54: =Sales_Fact[[#This Row],[Total_Amount]]/(Sales_Fact[[#This Row],[Quantity]]*(1-Sales_Fact[[#This Row],[Discount]])) -> 162.0211 | H54: 0 | I54: Credit Card | J54: 486.0633 | K54: =COUNTIF(Sales_Fact[Payment_Type], "Credit Card") -> 645 | L54: =IF(J54>=1000, "Good", "Average") -> Average
A55: SALE53 | B55: 45677 | C55: CUST1324 | D55: PROD20 | E55: STORE8 | F55: 1 | G55: 900.35 | H55: 0.13 | I55: COD | J55: 783.3045 | K55: =COUNTIF(Sales_Fact[Payment_Type], "Credit Card") -> 645 | L55: =IF(J55>=1000, "Good", "Average") -> Average
A56: SALE54 | B56: 45706 | C56: CUST1095 | D56: PROD40 | E56: STORE10 | F56: 4 | G56: 428.09 | H56: 0.07 | I56: Credit Card | J56: 1592.4948 | K56: =COUNTIF(Sales_Fact[Payment_Type], "Credit Card") -> 645 | L56: =IF(J56>=1000, "Good", "Average") -> Good
A57: SALE55 | B57: 45589 | C57: CUST1416 | D57: PROD49 | E57: STORE11 | F57: 2 | G57: 559.71 | H57: 0.3 | I57: COD | J57: 783.594 | K57: =COUNTIF(Sales_Fact[Payment_Type], "Credit Card") -> 645 | L57: =IF(J57>=1000, "Good", "Average") -> Average
A58: SALE56 | B58: 45282 | C58: CUST1080 | D58: PROD34 | E58: STORE6 | F58: 2 | G58: 833.7 | H58: 0.06 | I58: PayPal | J58: 1567.356 | K58: =COUNTIF(Sales_Fact[Payment_Type], "Credit Card") -> 645 | L58: =IF(J58>=1000, "Good", "Average") -> Good
...

Sheet XLookup Sheet
A1: Product_ID | B1: Unit_Price | C1: Quantity | D1: Payment_Type | E1: Total_Amount
A2: PROD97 | B2: =_xlfn.XLOOKUP(A2,Sales_Fact[Product_ID],Sales_Fact[Unit_Price],"Not Found") -> 218.04 | C2: =_xlfn.XLOOKUP(A2,Sales_Fact[Product_ID],Sales_Fact[Quantity],"Not Found") -> 1 | D2: =_xlfn.XLOOKUP(A2,Sales_Fact[Product_ID],Sales_Fact[Payment_Type],"Not Found") -> Credit Card | E2: =_xlfn.XLOOKUP(A2,Sales_Fact[Product_ID],Sales_Fact[Total_Amount],"Not Found") -> 198.4164
A3: PROD74 | B3: =_xlfn.XLOOKUP(A3,Sales_Fact[Product_ID],Sales_Fact[Unit_Price],"Not Found") -> 104.47 | C3: =_xlfn.XLOOKUP(A3,Sales_Fact[Product_ID],Sales_Fact[Quantity],"Not Found") -> 3 | D3: =_xlfn.XLOOKUP(A3,Sales_Fact[Product_ID],Sales_Fact[Payment_Type],"Not Found") -> PayPal | E3: =_xlfn.XLOOKUP(A3,Sales_Fact[Product_ID],Sales_Fact[Total_Amount],"Not Found") -> 228.7893
A4: PROD49 | B4: =_xlfn.XLOOKUP(A4,Sales_Fact[Product_ID],Sales_Fact[Unit_Price],"Not Found") -> 914.05 | C4: =_xlfn.XLOOKUP(A4,Sales_Fact[Product_ID],Sales_Fact[Quantity],"Not Found") -> 4 | D4: =_xlfn.XLOOKUP(A4,Sales_Fact[Product_ID],Sales_Fact[Payment_Type],"Not Found") -> Credit Card | E4: =_xlfn.XLOOKUP(A4,Sales_Fact[Product_ID],Sales_Fact[Total_Amount],"Not Found") -> 2742.15
A5: PROD76 | B5: =_xlfn.XLOOKUP(A5,Sales_Fact[Product_ID],Sales_Fact[Unit_Price],"Not Found") -> 921.51 | C5: =_xlfn.XLOOKUP(A5,Sales_Fact[Product_ID],Sales_Fact[Quantity],"Not Found") -> 1 | D5: =_xlfn.XLOOKUP(A5,Sales_Fact[Product_ID],Sales_Fact[Payment_Type],"Not Found") -> COD | E5: =_xlfn.XLOOKUP(A5,Sales_Fact[Product_ID],Sales_Fact[Total_Amount],"Not Found") -> 774.0684
A6: PROD59 | B6: =_xlfn.XLOOKUP(A6,Sales_Fact[Product_ID],Sales_Fact[Unit_Price],"Not Found") -> 745.3 | C6: =_xlfn.XLOOKUP(A6,Sales_Fact[Product_ID],Sales_Fact[Quantity],"Not Found") -> 3 | D6: =_xlfn.XLOOKUP(A6,Sales_Fact[Product_ID],Sales_Fact[Payment_Type],"Not Found") -> Credit Card | E6: =_xlfn.XLOOKUP(A6,Sales_Fact[Product_ID],Sales_Fact[Total_Amount],"Not Found") -> 1833.438
A7: PROD15 | B7: =_xlfn.XLOOKUP(A7,Sales_Fact[Product_ID],Sales_Fact[Unit_Price],"Not Found") -> 147.01 | C7: =_xlfn.XLOOKUP(A7,Sales_Fact[Product_ID],Sales_Fact[Quantity],"Not Found") -> 3 | D7: =_xlfn.XLOOKUP(A7,Sales_Fact[Product_ID],Sales_Fact[Payment_Type],"Not Found") -> COD | E7: =_xlfn.XLOOKUP(A7,Sales_Fact[Product_ID],Sales_Fact[Total_Amount],"Not Found") -> 357.2343
A8: PROD56 | B8: =_xlfn.XLOOKUP(A8,Sales_Fact[Product_ID],Sales_Fact[Unit_Price],"Not Found") -> 785.31 | C8: =_xlfn.XLOOKUP(A8,Sales_Fact[Product_ID],Sales_Fact[Quantity],"Not Found") -> 2 | D8: =_xlfn.XLOOKUP(A8,Sales_Fact[Product_ID],Sales_Fact[Payment_Type],"Not Found") -> PayPal | E8: =_xlfn.XLOOKUP(A8,Sales_Fact[Product_ID],Sales_Fact[Total_Amount],"Not Found") -> 1335.027
A9: PROD70 | B9: =_xlfn.XLOOKUP(A9,Sales_Fact[Product_ID],Sales_Fact[Unit_Price],"Not Found") -> 342.39 | C9: =_xlfn.XLOOKUP(A9,Sales_Fact[Product_ID],Sales_Fact[Quantity],"Not Found") -> 4 | D9: =_xlfn.XLOOKUP(A9,Sales_Fact[Product_ID],Sales_Fact[Payment_Type],"Not Found") -> PayPal | E9: =_xlfn.XLOOKUP(A9,Sales_Fact[Product_ID],Sales_Fact[Total_Amount],"Not Found") -> 1054.5612
A10: PROD99 | B10: =_xlfn.XLOOKUP(A10,Sales_Fact[Product_ID],Sales_Fact[Unit_Price],"Not Found") -> 448.25 | C10: =_xlfn.XLOOKUP(A10,Sales_Fact[Product_ID],Sales_Fact[Quantity],"Not Found") -> 2 | D10: =_xlfn.XLOOKUP(A10,Sales_Fact[Product_ID],Sales_Fact[Payment_Type],"Not Found") -> PayPal | E10: =_xlfn.XLOOKUP(A10,Sales_Fact[Product_ID],Sales_Fact[Total_Amount],"Not Found") -> 1250.6175
A11: PROD33 | B11: =_xlfn.XLOOKUP(A11,Sales_Fact[Product_ID],Sales_Fact[Unit_Price],"Not Found") -> 873.17 | C11: =_xlfn.XLOOKUP(A11,Sales_Fact[Product_ID],Sales_Fact[Quantity],"Not Found") -> 2 | D11: =_xlfn.XLOOKUP(A11,Sales_Fact[Product_ID],Sales_Fact[Payment_Type],"Not Found") -> PayPal | E11: =_xlfn.XLOOKUP(A11,Sales_Fact[Product_ID],Sales_Fact[Total_Amount],"Not Found") -> 1344.6818
A12: PROD24 | B12: =_xlfn.XLOOKUP(A12,Sales_Fact[Product_ID],Sales_Fact[Unit_Price],"Not Found") -> 278.63 | C12: =_xlfn.XLOOKUP(A12,Sales_Fact[Product_ID],Sales_Fact[Quantity],"Not Found") -> 1 | D12: =_xlfn.XLOOKUP(A12,Sales_Fact[Product_ID],Sales_Fact[Payment_Type],"Not Found") -> Credit Card | E12: =_xlfn.XLOOKUP(A12,Sales_Fact[Product_ID],Sales_Fact[Total_Amount],"Not Found") -> 259.1259
A13: PROD39 | B13: =_xlfn.XLOOKUP(A13,Sales_Fact[Product_ID],Sales_Fact[Unit_Price],"Not Found") -> 286.92 | C13: =_xlfn.XLOOKUP(A13,Sales_Fact[Product_ID],Sales_Fact[Quantity],"Not Found") -> 4 | D13: =_xlfn.XLOOKUP(A13,Sales_Fact[Product_ID],Sales_Fact[Payment_Type],"Not Found") -> Credit Card | E13: =_xlfn.XLOOKUP(A13,Sales_Fact[Product_ID],Sales_Fact[Total_Amount],"Not Found") -> 952.5744
... A2001: PROD76 | B2001: =_xlfn.XLOOKUP(A2001,Sales_Fact[Product_ID],Sales_Fact[Unit_Price],"Not Found") -> 921.51 | C2001: =_xlfn.XLOOKUP(A2001,Sales_Fact[Product_ID],Sales_Fact[Quantity],"Not Found") -> 1 | D2001: =_xlfn.XLOOKUP(A2001,Sales_Fact[Product_ID],Sales_Fact[Payment_Type],"Not Found") -> COD | E2001: =_xlfn.XLOOKUP(A2001,Sales_Fact[Product_ID],Sales_Fact[Total_Amount],"Not Found") -> 774.0684

Sheet VLOOKUP Sheet
A1: Product_ID | B1: Category | C1: Sub_Category | D1: Cost
A2: PROD0 | B2: =VLOOKUP(A2,'Cleaned Product_Dim '!$A$2:$H$101,3,0) -> Electronics | C2: =VLOOKUP(A2,'Cleaned Product_Dim '!$A2:$H101,4,0) -> Computer | D2: =VLOOKUP(A2,'Cleaned Product_Dim '!$A2:$H101,6,0) -> 112.42
A3: PROD1 | B3: =VLOOKUP(A3,'Cleaned Product_Dim '!$A$2:$H$101,3,0) -> Clothing | C3: =VLOOKUP(A3,'Cleaned Product_Dim '!$A3:$H102,4,0) -> Tops | D3: =VLOOKUP(A3,'Cleaned Product_Dim '!$A3:$H102,6,0) -> 342.56
A4: PROD2 | B4: =VLOOKUP(A4,'Cleaned Product_Dim '!$A$2:$H$101,3,0) -> Clothing | C4: =VLOOKUP(A4,'Cleaned Product_Dim '!$A4:$H103,4,0) -> Outerwear | D4: =VLOOKUP(A4,'Cleaned Product_Dim '!$A4:$H103,6,0) -> 358.47
A5: PROD3 | B5: =VLOOKUP(A5,'Cleaned Product_Dim '!$A$2:$H$101,3,0) -> Clothing | C5: =VLOOKUP(A5,'Cleaned Product_Dim '!$A5:$H104,4,0) -> Outerwear | D5: =VLOOKUP(A5,'Cleaned Product_Dim '!$A5:$H104,6,0) -> 364.67
A6: PROD4 | B6: =VLOOKUP(A6,'Cleaned Product_Dim '!$A$2:$H$101,3,0) -> Clothing | C6: =VLOOKUP(A6,'Cleaned Product_Dim '!$A6:$H105,4,0) -> Bottoms | D6: =VLOOKUP(A6,'Cleaned Product_Dim '!$A6:$H105,6,0) -> 306.46
A7: PROD5 | B7: =VLOOKUP(A7,'Cleaned Product_Dim '!$A$2:$H$101,3,0) -> Clothing | C7: =VLOOKUP(A7,'Cleaned Product_Dim '!$A7:$H106,4,0) -> Accessories | D7: =VLOOKUP(A7,'Cleaned Product_Dim '!$A7:$H106,6,0) -> 261
A8: PROD6 | B8: =VLOOKUP(A8,'Cleaned Product_Dim '!$A$2:$H$101,3,0) -> Beauty | C8: =VLOOKUP(A8,'Cleaned Product_Dim '!$A8:$H107,4,0) -> Skincare | D8: =VLOOKUP(A8,'Cleaned Product_Dim '!$A8:$H107,6,0) -> 312.8
A9: PROD7 | B9: =VLOOKUP(A9,'Cleaned Product_Dim '!$A$2:$H$101,3,0) -> Home | C9: =VLOOKUP(A9,'Cleaned Product_Dim '!$A9:$H108,4,0) -> Lighting | D9: =VLOOKUP(A9,'Cleaned Product_Dim '!$A9:$H108,6,0) -> 218.86
A10: PROD8 | B10: =VLOOKUP(A10,'Cleaned Product_Dim '!$A$2:$H$101,3,0) -> Electronics | C10: =VLOOKUP(A10,'Cleaned Product_Dim '!$A10:$H109,4,0) -> Audio | D10: =VLOOKUP(A10,'Cleaned Product_Dim '!$A10:$H109,6,0) -> 439.07
A11: PROD9 | B11: =VLOOKUP(A11,'Cleaned Product_Dim '!$A$2:$H$101,3,0) -> Sports | C11: =VLOOKUP(A11,'Cleaned Product_Dim '!$A11:$H110,4,0) -> Fitness | D11: =VLOOKUP(A11,'Cleaned Product_Dim '!$A11:$H110,6,0) -> 495.72
A12: PROD10 | B12: =VLOOKUP(A12,'Cleaned Product_Dim '!$A$2:$H$101,3,0) -> Home | C12: =VLOOKUP(A12,'Cleaned Product_Dim '!$A12:$H111,4,0) -> Kitchen | D12: =VLOOKUP(A12,'Cleaned Product_Dim '!$A12:$H111,6,0) -> 298.86
A13: PROD11 | B13: =VLOOKUP(A13,'Cleaned Product_Dim '!$A$2:$H$101,3,0) -> Electronics | C13: =VLOOKUP(A13,'Cleaned Product_Dim '!$A13:$H112,4,0) -> Accessories | D13: =VLOOKUP(A13,'Cleaned Product_Dim '!$A13:$H112,6,0) -> 449.4
... A101: PROD99 | B101: =VLOOKUP(A101,'Cleaned Product_Dim '!$A$2:$H$101,3,0) -> Home | C101: =VLOOKUP(A101,'Cleaned Product_Dim '!$A101:$H200,4,0) -> Kitchen | D101: =VLOOKUP(A101,'Cleaned Product_Dim '!$A101:$H200,6,0) -> 201.41

Sheet  Customer pivot
A3: Row Labels | B3: Count of Gender
A4: Bronze | B4: 126
A5: Female | B5: 60
A6: Male | B6: 66
A7: Gold | B7: 122
A8: Female | B8: 68
A9: Male | B9: 54
A10: Platinum | B10: 147
A11: Female | B11: 82
A12: Male | B12: 65
A13: Silver | B13: 105
A14: Female | B14: 52
A15: Male | B15: 53
A16: Grand Total | B16: 500

Sheet Product Pivot
A3: Row Labels | B3: Count of Cost | C3: Sum of Stock
A4: Accessories | B4: 17 | C4: 4603
A5: Clothing | B5: 4 | C5: 1022
A6: Electronics | B6: 7 | C6: 2303
A7: Sports | B7: 6 | C7: 1278
A8: Appliances | B8: 3 | C8: 596
A9: Electronics | B9: 2 | C9: 405
A10: Home | B10: 1 | C10: 191
A11: Audio | B11: 5 | C11: 965
A12: Electronics | B12: 5 | C12: 965
A13: Bottoms | B13: 4 | C13: 1179
A14: Clothing | B14: 4 | C14: 1179
A15: Computer | B15: 6 | C15: 1795
... A53: Grand Total | B53: 100 | C53: 27312

Sheet Store Pivot
A3: Row Labels | B3: Sum of Store count
A4: East | B4: 48
A5: Flagship | B5: 24
A6: STORE0 | B6: 8
A7: STORE13 | B7: 8
A8: STORE18 | B8: 8
A9: Online | B9: 24
A10: STORE10 | B10: 8
A11: STORE19 | B11: 8
A12: STORE6 | B12: 8
A13: North | B13: 40
A14: Flagship | B14: 24
A15: STORE1 | B15: 8
... A38: Grand Total | B38: 144

Sheet Sales Pivot
A3: Row Labels | B3: Sum of Quantity | C3: Sum of Unit_Price | D3: Sum of Discount
A4: STORE0 | B4: 204 | C4: 45428.07 | D4: 12.96
A5: COD | B5: 85 | C5: 19644.34 | D5: 5.68
A6: Credit Card | B6: 57 | C6: 11149.4 | D6: 3.66
A7: PayPal | B7: 62 | C7: 14634.33 | D7: 3.62
A8: STORE1 | B8: 231 | C8: 45728.85 | D8: 12.84
A9: COD | B9: 72 | C9: 14195.23 | D9: 3.43
A10: Credit Card | B10: 78 | C10: 12688.71 | D10: 5.14
A11: PayPal | B11: 81 | C11: 18844.91 | D11: 4.27
A12: STORE10 | B12: 255 | C12: 50006.16 | D12: 15.14
A13: COD | B13: 93 | C13: 18147.12 | D13: 5.78
A14: Credit Card | B14: 74 | C14: 15796.66 | D14: 4.22
A15: PayPal | B15: 88 | C15: 16062.38 | D15: 5.14
... A84: Grand Total | B84: 4958 | C84: 1027165.6 | D84: 295.92
